<?xml version="1.0"?>
<robot xmlns:xacro="http://www.ros.org/wiki/xacro" name="my_robot">

  <xacro:macro name="inertial_box" params="mass x y z">
    <inertial>
      <origin xyz="0 0 0" rpy="0 0 0"/>
      <mass value="${mass}" />
      <inertia ixx="${(1/12) * mass * (y*y+z*z)}" ixy="0.0" ixz="0.0"
               iyy="${(1/12) * mass * (x*x+z*z)}" iyz="0.0"
               izz="${(1/12) * mass * (x*x+y*y)}" />
    </inertial>
  </xacro:macro>

  <xacro:macro name="inertial_cylinder" params="mass length radius">
    <inertial>
      <origin xyz="0 0 0" rpy="0 0 0"/>
      <mass value="${mass}" />
      <inertia ixx="${(1/12) * mass * (3*radius*radius + length*length)}" ixy="0.0" ixz="0.0"
               iyy="${(1/12) * mass * (3*radius*radius + length*length)}" iyz="0.0"
               izz="${(1/2) * mass * (radius*radius)}" />
    </inertial>
  </xacro:macro>

  <link name="base_footprint"></link>

  <joint name="base_joint" type="fixed">
    <parent link="base_footprint"/>
    <child link="base_link"/>
    <origin xyz="0 0 0.3" rpy="0 0 0"/>
  </joint>

  <link name="base_link">
    <visual>
      <geometry><box size="0.4 0.4 0.4"/></geometry>
      <material name="blue"><color rgba="0 0 1 1"/></material>
    </visual>
    <collision>
      <geometry><box size="0.4 0.4 0.4"/></geometry>
    </collision>
    <xacro:inertial_box mass="6.0" x="0.4" y="0.4" z="0.4"/>
  </link>

  <link name="fork_link">
    <visual>
      <geometry><box size="0.3 0.3 0.05"/></geometry>
      <material name="gray"><color rgba="0.7 0.7 0.7 1"/></material>
    </visual>
    <collision>
      <geometry><box size="0.3 0.3 0.05"/></geometry>
    </collision>
    <xacro:inertial_box mass="1.0" x="0.3" y="0.3" z="0.05"/>
  </link>

  <joint name="fork_joint" type="fixed">
    <parent link="base_link"/>
    <child link="fork_link"/>
    <origin xyz="0.35 0 -0.175" rpy="0 0 0"/> 
  </joint>

  <link name="lidar_link">
    <visual>
      <geometry><cylinder radius="0.05" length="0.05"/></geometry>
      <material name="red"><color rgba="1 0 0 1"/></material>
    </visual>
    <collision>
      <geometry><cylinder radius="0.05" length="0.05"/></geometry>
    </collision>
    <xacro:inertial_cylinder mass="0.2" length="0.05" radius="0.05"/>
  </link>

  <joint name="lidar_link_joint" type="fixed">
    <parent link="base_link"/>
    <child link="lidar_link"/>
    <origin xyz="0 0 0.22" rpy="0 0 0"/> </joint>

  <xacro:macro name="wheel" params="prefix x_val y_val">
    <link name="${prefix}_wheel">
      <visual>
        <origin rpy="1.5708 0 0"/> 
        <geometry><cylinder radius="0.1" length="0.05"/></geometry>
        <material name="black"><color rgba="0 0 0 1"/></material>
      </visual>
      
      <collision>
        <origin rpy="1.5708 0 0"/>
        <geometry><cylinder radius="0.1" length="0.05"/></geometry>
      </collision>

      <xacro:inertial_cylinder mass="0.5" length="0.05" radius="0.1"/>
    </link>

    <joint name="${prefix}_wheel_joint" type="continuous">
      <parent link="base_link"/>
      <child link="${prefix}_wheel"/>
      <origin xyz="${x_val} ${y_val} -0.2" rpy="0 0 0"/>
      <axis xyz="0 1 0"/> 
      <dynamics damping="0.2" friction="0.2"/>
    </joint>

    <gazebo reference="${prefix}_wheel">
      <mu1>200.0</mu1>
      <mu2>200.0</mu2>
      <kp>1000000.0</kp>     
      <kd>1.0</kd>            
      <fdir1>1 0 0</fdir1>           
    </gazebo>
  </xacro:macro>

  <xacro:wheel prefix="front_left"  x_val="0.15"  y_val="0.235"/>
  <xacro:wheel prefix="front_right" x_val="0.15"  y_val="-0.235"/>
  <xacro:wheel prefix="rear_left"   x_val="-0.15" y_val="0.235"/>
  <xacro:wheel prefix="rear_right"  x_val="-0.15" y_val="-0.235"/>

  <link name="imu_link"/> 

  <joint name="imu_joint" type="fixed">
    <parent link="base_link"/>
    <child link="imu_link"/>
    <origin xyz="0 0 0" rpy="0 0 0"/>
  </joint>

  <gazebo reference="imu_link">
   <sensor name="imu_sensor" type="imu">
      <always_on>true</always_on>
      <update_rate>100</update_rate>
      <visualize>true</visualize>

      <plugin filename="libgazebo_ros_imu_sensor.so" name="imu_plugin">
        <ros>
         <remapping>~/out:=imu/data</remapping>
        </ros>
        <initial_orientation_as_reference>false</initial_orientation_as_reference>
      </plugin>
    </sensor>
  </gazebo>

  <gazebo>
    <plugin name="skid_steer_drive" filename="libgazebo_ros_diff_drive.so">
      <update_rate>100</update_rate>
      <num_wheel_pairs>2</num_wheel_pairs>

      <left_joint>front_left_wheel_joint</left_joint>
      <right_joint>front_right_wheel_joint</right_joint>

      <left_joint>rear_left_wheel_joint</left_joint>
      <right_joint>rear_right_wheel_joint</right_joint>

      <wheel_separation>0.45</wheel_separation> 
      <wheel_diameter>0.2</wheel_diameter>     

      <max_wheel_torque>200</max_wheel_torque>
      <max_wheel_acceleration>10.0</max_wheel_acceleration>

      <covariance_x>0.0001</covariance_x>
      <covariance_y>0.0001</covariance_y>
      <covariance_yaw>0.01</covariance_yaw>

      <publish_odom>true</publish_odom>
      <publish_odom_tf>true</publish_odom_tf>
      <publish_wheel_tf>true</publish_wheel_tf>

      <odometry_source>1</odometry_source>

      <odometry_frame>odom</odometry_frame>
      <robot_base_frame>base_footprint</robot_base_frame>
    </plugin>
  </gazebo>

  <gazebo reference="lidar_link">
    <sensor name="lidar_3d" type="ray">
      <always_on>true</always_on>
      <visualize>false</visualize> 
      <update_rate>10</update_rate> 
      
      <ray>
        <scan>
          <horizontal>
            <samples>360</samples> 
            <resolution>1.0</resolution>
            <min_angle>-3.14159</min_angle>
            <max_angle>3.14159</max_angle> 
          </horizontal>
          <vertical>
            <samples>16</samples> 
            <resolution>1.0</resolution>
            <min_angle>-0.261799</min_angle> 
            <max_angle>0.261799</max_angle> 
          </vertical>
        </scan>
        <range>
          <min>0.40</min>
          <max>12.0</max>
          <resolution>0.015</resolution>
        </range>
        <noise>
          <type>gaussian</type>
          <mean>0.0</mean>
          <stddev>0.01</stddev> 
        </noise>
      </ray>

      <plugin name="scan_3d" filename="libgazebo_ros_ray_sensor.so">
        <ros>
          <remapping>~/out:=points</remapping>
        </ros>
        <output_type>sensor_msgs/PointCloud2</output_type>
        <frame_name>lidar_link</frame_name>
      </plugin>
    </sensor>
  </gazebo>

  <gazebo>
    <plugin name="wheel_encoder_plugin" filename="libgazebo_ros_joint_state_publisher.so">
      <ros>
        <namespace>/</namespace>
        <remapping>joint_states:=wheel_encoders</remapping>
      </ros>
      <update_rate>30.0</update_rate>
      
      <joint_name>front_left_wheel_joint</joint_name>
      <joint_name>front_right_wheel_joint</joint_name>
      <joint_name>rear_left_wheel_joint</joint_name>
      <joint_name>rear_right_wheel_joint</joint_name>
    </plugin>
  </gazebo>

</robot>